Workbook

Sheet NOTES
A1: New York City Department of Education
A2: Report on PTA and PA Financial Reporting, 2019
A3: Local Law No. 171
A4: Notes
A5: This is a Local Law to amend the administrative code of the city of New York, in relation to requiring the reporting of information regarding parent-teacher association and parent association chapters in public schools.
A6: PA/PTAs in NYC are governed by Chancellor’s Regulation A660 and NYS Law §2590-h.15 (a) which states that every public school in NYC, under the Chancellor's jurisdiction, must establish a PA or PTA.
A7: Per Chancellor's Regulation A-660: • PA/PTAs are autonomous and self-governing. School officials’ oversight of PA/PTAs is limited to what is necessary to implement and enforce laws, policies, rules and regulations, and to protect the rights of students, parents and staff. - A660. INTRODUCTION • PA/PTAs must be responsible for their own financial affairs. PA/PTA funds are separate and independent from school, district, borough, or personal funds. PA/PTA funds are not included in determining school, district, or borough budgets. - A660. III. FINANCIAL AFFAIRS OF PARENT ASSOCIATIONS AND PRESIDENTS’ COUNCILS • An Interim PA/PTA Financial Report must be prepared by the PA/PTA and submitted to the principal by January 31 of each school year. An Annual PA/PTA Financial Report must be prepared by the PA/PTA and submitted to the principal by June 30 of each school year. – A660. III. F. 2. PA/PTA AND PRESIDENTS’ COUNCIL FINANCIAL REPORTS • PA/PTA and Presidents’ Council fundraisers are not ends in themselves. They must be tied to the goals of the organization, including parent education, workshops, and school, district, or borough initiatives. Proceeds from fundraisers must be used to supplement or complement the educational, social and cultural programs of schools, districts, or boroughs. On a case-by-case basis, the Chancellor may permit PA/PTAs and Presidents’ Councils to raise funds for humanitarian causes. - A660. III. C. PA/PTA AND PRESIDENTS' COUNCIL FUNDRAISING • PA/PTA fundraising activities involving students during instructional hours are restricted to 2 per year. There are no restrictions on the number of fundraising activities during non-instructional hours. Non-instructional hours are defined as time during the school day when students are not engaged in the instructional process (e.g., lunch time). The principal’s written consent is only required when the fundraising activity is held during school hours or on school property. - A660. III .3. PA/PTA FUNDRAISER PLANNING
A8: DOE oversight is limited. Annual collection of the PA/PTA Interim and Annual Financial Report is on the Compliance Checklist #CL12
A9: Data is self-reported. PA/PTAs maintain their own records. They are required to submit an interim and annual financial report on paper to their principal. Principals and parent coordinators then manually enter the data into the School Parent Leadership Contact Information (SPLCI) database.
A10: Pre-K centers, Alternative Schools (D79), and Charter Schools (D84) are not required to have a PA/PTA and are therefore not included in this report.
A11: School demographic data is extracted from the Demographic Snapshot on the DOE public website. For more data on NYC schools, visit: https://infohub.nyced.org/reports-and-policies/citywide-information-and-data/information-and-data-overview

Sheet Citywide
A1: City | B1: Beginning Balance | C1: Total Income | D1: Total Expenses | E1: Ending Balance
A2: CITYWIDE | B2: =SUM('Community School District'!B2:B34) -> 87490708 | C2: =SUM('Community School District'!C2:C34) -> 1.8876294e+08 | D2: =SUM('Community School District'!D2:D34) -> 2.1377615e+08 | E2: =SUM('Community School District'!E2:E34) -> 77573876

Sheet Community School District
A1: District | B1: Beginning Balance | C1: Total Income | D1: Total Expenses | E1: Ending Balance
A2: 1 | B2: =SUM(School!D2:D29) -> 1240470.3 | C2: =SUM(School!E2:E29) -> 7123105.9 | D2: =SUM(School!F2:F29) -> 34327561 | E2: =SUM(School!G2:G29) -> 1495744.9
A3: 2 | B3: =SUM(School!D30:D147) -> 14201765 | C3: =SUM(School!E30:E147) -> 18528871 | D3: =SUM(School!F30:F147) -> 16253533 | E3: =SUM(School!G30:G147) -> 12503617
A4: 3 | B4: =SUM(School!D148:D191) -> 7529891.4 | C4: =SUM(School!E148:E191) -> 10289076 | D4: =SUM(School!F148:F191) -> 6745714.3 | E4: =SUM(School!G148:G191) -> 7357085.2
A5: 4 | B5: =SUM(School!D192:D220) -> 429009.44 | C5: =SUM(School!E192:E220) -> 508766.05 | D5: =SUM(School!F192:F220) -> 498362.5 | E5: =SUM(School!G192:G220) -> 423113.06
A6: 5 | B6: =SUM(School!D221:D247) -> 161818.13 | C6: =SUM(School!E221:E247) -> 444699.57 | D6: =SUM(School!F221:F247) -> 340458.95 | E6: =SUM(School!G221:G247) -> 166816.75
A7: 6 | B7: =SUM(School!D248:D293) -> 242117.97 | C7: =SUM(School!E248:E293) -> 547321.83 | D7: =SUM(School!F248:F293) -> 421942.64 | E7: =SUM(School!G248:G293) -> 264223.17
A8: 7 | B8: =SUM(School!D294:D333) -> 23118.82 | C8: =SUM(School!E294:E333) -> 545869.67 | D8: =SUM(School!F294:F333) -> 64809.04 | E8: =SUM(School!G294:G333) -> 38872.25
A9: 8 | B9: =SUM(School!D334:D385) -> 2235477.7 | C9: =SUM(School!E334:E385) -> 3955641.4 | D9: =SUM(School!F334:F385) -> 340257.87 | E9: =SUM(School!G334:G385) -> 73232.05
A10: 9 | B10: =SUM(School!D386:D454) -> 43894.04 | C10: =SUM(School!E386:E454) -> 125429.1 | D10: =SUM(School!F386:F454) -> 115139.29 | E10: =SUM(School!G386:G454) -> 27035.9
A11: 10 | B11: =SUM(School!D455:D538) -> 2428853.8 | C11: =SUM(School!E455:E538) -> 4244920.6 | D11: =SUM(School!F455:F538) -> 2386241.2 | E11: =SUM(School!G455:G538) -> 2088180.7
A12: 11 | B12: =SUM(School!D539:D600) -> 120789.16 | C12: =SUM(School!E539:E600) -> 390603.11 | D12: =SUM(School!F539:F600) -> 1771159.9 | E12: =SUM(School!G539:G600) -> 388772.02
A13: 12 | B13: =SUM(School!D601:D647) -> 14261.66 | C13: =SUM(School!E601:E647) -> 53211.22 | D13: =SUM(School!F601:F647) -> 44378.32 | E13: =SUM(School!G601:G647) -> 12067.44
A14: 13 | B14: =SUM(School!D648:D688) -> 45014658 | C14: =SUM(School!E648:E688) -> 80262706 | D14: =SUM(School!F648:F688) -> 77784185 | E14: =SUM(School!G648:G688) -> 29513915
A15: 14 | B15: =SUM(School!D689:D726) -> 1485997.1 | C15: =SUM(School!E689:E726) -> 6656597.5 | D15: =SUM(School!F689:F726) -> 685919.71 | E15: =SUM(School!G689:G726) -> 559301.63
A16: 15 | B16: =SUM(School!D727:D774) -> 3433409 | C16: =SUM(School!E727:E774) -> 11423547 | D16: =SUM(School!F727:F774) -> 8979153.2 | E16: =SUM(School!G727:G774) -> 3770006.5
A17: 16 | B17: =SUM(School!D775:D798) -> 14814.85 | C17: =SUM(School!E775:E798) -> 87921.91 | D17: =SUM(School!F775:F798) -> 83311.89 | E17: =SUM(School!G775:G798) -> 10278.31
A18: 17 | B18: =SUM(School!D799:D847) -> 120775.76 | C18: =SUM(School!E799:E847) -> 332809.37 | D18: =SUM(School!F799:F847) -> 266159.04 | E18: =SUM(School!G799:G847) -> 1145286.1
A19: 18 | B19: =SUM(School!D848:D880) -> 34668.63 | C19: =SUM(School!E848:E880) -> 153104.21 | D19: =SUM(School!F848:F880) -> 121126.2 | E19: =SUM(School!G848:G880) -> 26110.8
A20: 19 | B20: =SUM(School!D881:D929) -> 53200.35 | C20: =SUM(School!E881:E929) -> 180264.33 | D20: =SUM(School!F881:F929) -> 153010.29 | E20: =SUM(School!G881:G929) -> 51216.04
A21: 20 | B21: =SUM(School!D930:D972) -> 1220477.6 | C21: =SUM(School!E930:E972) -> 8091721.4 | D21: =SUM(School!F930:F972) -> 2217613.4 | E21: =SUM(School!G930:G972) -> 5047864.9
A22: 21 | B22: =SUM(School!D973:D1012) -> 212861.23 | C22: =SUM(School!E973:E1012) -> 1226910.3 | D22: =SUM(School!F973:F1012) -> 1046775.3 | E22: =SUM(School!G973:G1012) -> 197011.14
A23: 22 | B23: =SUM(School!D1013:D1052) -> 406728.73 | C23: =SUM(School!E1013:E1052) -> 1388206.4 | D23: =SUM(School!F1013:F1052) -> 1199976.1 | E23: =SUM(School!G1013:G1052) -> 430554.88
A24: 23 | B24: =SUM(School!D1053:D1080) -> 15125.8 | C24: =SUM(School!E1053:E1080) -> 73233.33 | D24: =SUM(School!F1053:F1080) -> 84083.06 | E24: =SUM(School!G1053:G1080) -> 20295.55
A25: 24 | B25: =SUM(School!D1081:D1135) -> 947854.43 | C25: =SUM(School!E1081:E1135) -> 1608053.6 | D25: =SUM(School!F1081:F1135) -> 1278562.9 | E25: =SUM(School!G1081:G1135) -> 401802.35
A26: 25 | B26: =SUM(School!D1136:D1181) -> 448276.97 | C26: =SUM(School!E1136:E1181) -> 1362459.3 | D26: =SUM(School!F1136:F1181) -> 5322058.2 | E26: =SUM(School!G1136:G1181) -> 417479.3
A27: 26 | B27: =SUM(School!D1182:D1214) -> 653451.27 | C27: =SUM(School!E1182:E1214) -> 3818853.5 | D27: =SUM(School!F1182:F1214) -> 1632818.1 | E27: =SUM(School!G1182:G1214) -> 651614.55
A28: 27 | B28: =SUM(School!D1215:D1277) -> 385383.54 | C28: =SUM(School!E1215:E1277) -> 1336463.1 | D28: =SUM(School!F1215:F1277) -> 1049020.6 | E28: =SUM(School!G1215:G1277) -> 663611.43
A29: 28 | B29: =SUM(School!D1278:D1327) -> 1444043.6 | C29: =SUM(School!E1278:E1327) -> 4294114.3 | D29: =SUM(School!F1278:F1327) -> 3184509.5 | E29: =SUM(School!G1278:G1327) -> 6904535.9
A30: 29 | B30: =SUM(School!D1328:D1373) -> 83018.8 | C30: =SUM(School!E1328:E1373) -> 389153.15 | D30: =SUM(School!F1328:F1373) -> 345389.9 | E30: =SUM(School!G1328:G1373) -> 73825.36
A31: 30 | B31: =SUM(School!D1374:D1422) -> 767557.6 | C31: =SUM(School!E1374:E1422) -> 6333283.4 | D31: =SUM(School!F1374:F1422) -> 33328275 | E31: =SUM(School!G1374:G1422) -> 919879.11
A32: 31 | B32: =SUM(School!D1423:D1494) -> 1699301.2 | C32: =SUM(School!E1423:E1494) -> 12473497 | D32: =SUM(School!F1423:F1494) -> 11401206 | E32: =SUM(School!G1423:G1494) -> 1687770.7
A33: 32 | B33: =SUM(School!D1495:D1521) -> 19294.08 | C33: =SUM(School!E1495:E1521) -> 127063.44 | D33: =SUM(School!F1495:F1521) -> 117080.35 | E33: =SUM(School!G1495:G1521) -> 13689.02
A34: 75 | B34: =SUM(School!D1522:D1580) -> 358341.38 | C34: =SUM(School!E1522:E1580) -> 385457.34 | D34: =SUM(School!F1522:F1580) -> 186358.76 | E34: =SUM(School!G1522:G1580) -> 229066.09

Sheet School
A1: DBN | B1: School Name | C1: School Code | D1: Beginning Balance | E1: Total Income | F1: Total Expenses | G1: Ending Balance
A2: 01M015 | B2: P.S. 015 Roberto Clemente | C2: M015 | D2: 5.66 | E2: 276 | F2: 0 | G2: 281.66
A3: 01M019 | B3: P.S. 019 Asher Levy | C3: M019 | D3: 8500 | E3: 22318.82 | F3: 13964.36 | G3: 8354.46
A4: 01M020 | B4: P.S. 020 Anna Silver | C4: M020 | D4: 30303.69 | E4: 101140.91 | F4: 93918.84 | G4: 37525.76
A5: 01M034 | B5: P.S. 034 Franklin D. Roosevelt | C5: M034 | D5: 49.54 | E5: 8439.93 | F5: 7720.16 | G5: 719.77
A6: 01M063 | B6: The STAR Academy - P.S.63 | C6: M063 | D6: 11919.01 | E6: 13400.62 | F6: 12569.66 | G6: 12749.97
A7: 01M064 | B7: P.S. 064 Robert Simon | C7: M064 | D7: 2084.79 | E7: 5712.5 | F7: 6259 | G7: 1538.29
A8: 01M110 | B8: P.S. 110 Florence Nightingale | C8: M110 | D8: 61617.51 | E8: 4457595 | F8: 6669346 | G8: 39600
A9: 01M134 | B9: P.S. 134 Henrietta Szold | C9: M134 | D9: 9852.99 | E9: 21957.09 | F9: 19981.63 | G9: 1975.46
A10: 01M140 | B10: P.S. 140 Nathan Straus | C10: M140 | D10: 385 | E10: 10015.9 | F10: 9997.66 | G10: 18.24
A11: 01M142 | B11: P.S. 142 Amalia Castro | C11: M142 | D11: 0 | E11: 1594 | F11: 1370.09 | G11: 223.1
A12: 01M184 | B12: P.S. 184m Shuang Wen | C12: M184 | D12: 106834.57 | E12: 111622.74 | F12: 80660.96 | G12: 137796.35
A13: 01M188 | B13: P.S. 188 The Island School | C13: M188 | D13: 3485.38 | E13: 3485.38 | F13: 277.45 | G13: 3207.93
A14: 01M292 | B14: Orchard Collegiate Academy | C14: M292
A15: 01M315 | B15: The East Village Community School | C15: M315 | D15: 114530.64 | E15: 231777.51 | F15: 142160.57 | G15: 89616.94
A16: 01M332 | B16: University Neighborhood Middle School | C16: M332
A17: 01M361 | B17: The Children's Workshop School | C17: M361 | D17: 92439 | E17: 134233 | F17: 109943 | G17: 116729
A18: 01M363 | B18: Neighborhood School | C18: M363
A19: 01M364 | B19: Earth School | C19: M364 | D19: 121777 | E19: 116000 | F19: 106689 | G19: 131088
A20: 01M378 | B20: School for Global Leaders | C20: M378
A21: 01M448 | B21: University Neighborhood High School | C21: M448 | D21: 521.55 | E21: 0 | F21: 0 | G21: 521.55
A22: 01M450 | B22: East Side Community School | C22: M450 | D22: 14726.88 | E22: 20909.6 | F22: 20696.72 | G22: 14939.76
A23: 01M458 | B23: Forsyth Satellite Academy | C23: M458 | D23: 338.54 | E23: 304.39 | F23: 559.66 | G23: 83.27
A24: 01M509 | B24: Marta Valle High School | C24: M509 | D24: 0 | E24: 0 | F24: 0 | G24: 0
A25: 01M515 | B25: Lower East Side Preparatory High School | C25: M515 | D25: 0 | E25: 0 | F25: 0 | G25: 0
A26: 01M539 | B26: New Explorations into Science, Technology and Math High School | C26: M539 | D26: 542257 | E26: 1479000 | F26: 1302000 | G26: 719257
A27: 01M650 | B27: Cascades High School | C27: M650 | D27: 0 | E27: 0 | F27: 0 | G27: 0
A28: 01M696 | B28: Bard High School Early College | C28: M696 | D28: 101207.37 | E28: 317604.51 | F28: 25681247 | G28: 161999.41
A29: 01M839 | B29: Tompkins Square Middle School | C29: M839 | D29: 17634.22 | E29: 65718 | F29: 48199 | G29: 17519
A30: 02M001 | B30: P.S. 001 Alfred E. Smith | C30: M001 | D30: 29137.34 | E30: 13018.43 | F30: 2661.44 | G30: 39494.33
A31: 02M002 | B31: P.S. 002 Meyer London | C31: M002 | D31: 6806.76 | E31: 42104.02 | F31: 31470.53 | G31: 10633.49
A32: 02M003 | B32: P.S. 003 Charrette School | C32: M003 | D32: 411932.72 | E32: 524672.67 | F32: 646506.77 | G32: 290098.62
A33: 02M006 | B33: P.S. 006 Lillie D. Blake | C33: M006 | D33: 1220153 | E33: 936143.84 | F33: 1068005.3 | G33: 1033236.9
A34: 02M011 | B34: P.S. 011 William T. Harris | C34: M011
A35: 02M033 | B35: P.S. 033 Chelsea Prep | C35: M033 | D35: 284208 | E35: 515398 | F35: 397937 | G35: 117462
A36: 02M040 | B36: P.S. 040 Augustus Saint-Gaudens | C36: M040 | D36: 666144 | E36: 498759 | F36: 561676 | G36: 603226
A37: 02M041 | B37: P.S. 041 Greenwich Village | C37: M041 | D37: 627391 | E37: 1023319 | F37: 975740 | G37: 673784.68
A38: 02M042 | B38: P.S. 042 Benjamin Altman | C38: M042
A39: 02M047 | B39: 47 The American Sign Language and English Secondary School | C39: M047 | D39: 0 | E39: 0 | F39: 0 | G39: 0
A40: 02M051 | B40: P.S. 051 Elias Howe | C40: M051 | D40: 32537.45 | E40: 48852.36 | F40: 42634.69 | G40: 38755.12
...

Sheet Student Demographics
A1: DBN | B1: School Name | C1: Year | D1: Total Enrollment | E1: Grade PK (Half Day & Full Day) | F1: Grade K | G1: Grade 1 | H1: Grade 2 | I1: Grade 3 | J1: Grade 4 | K1: Grade 5 | L1: Grade 6 | M1: Grade 7 | N1: Grade 8 | O1: Grade 9 | P1: Grade 10 | Q1: Grade 11 | R1: Grade 12 | S1: # Female | T1: % Female | U1: # Male | V1: % Male | W1: # Asian | X1: % Asian | Y1: # Black | Z1: % Black | AA1: # Hispanic | AB1: % Hispanic | AC1: # Multiple Race Categories Not Represented | AD1: % Multiple Race Categories Not Represented | AE1: # White | AF1: % White | AG1: # Students with Disabilities | AH1: % Students with Disabilities | AI1: # English Language Learners | AJ1: % English Language Learners | AK1: # Poverty | AL1: % Poverty | AM1: Economic Need Index
A2: 01M015 | B2: P.S. 015 Roberto Clemente | C2: 2014-15 | D2: 183 | E2: 18 | F2: 27 | G2: 47 | H2: 31 | I2: 19 | J2: 17 | K2: 24 | L2: 0 | M2: 0 | N2: 0 | O2: 0 | P2: 0 | Q2: 0 | R2: 0 | S2: 84 | T2: 0.45901638 | U2: 99 | V2: 0.54098362 | W2: 8 | X2: 0.043715846 | Y2: 65 | Z2: 0.35519126 | AA2: 107 | AB2: 0.58469945 | AC2: 1 | AD2: 0.0054644807 | AE2: 2 | AF2: 0.010928961 | AG2: 64 | AH2: 0.34972677 | AI2: 17 | AJ2: 0.092896178 | AK2: 169 | AL2: 0.92349726 | AM2: 0.92992115
A3: 01M015 | B3: P.S. 015 Roberto Clemente | C3: 2015-16 | D3: 176 | E3: 14 | F3: 32 | G3: 33 | H3: 39 | I3: 23 | J3: 17 | K3: 18 | L3: 0 | M3: 0 | N3: 0 | O3: 0 | P3: 0 | Q3: 0 | R3: 0 | S3: 83 | T3: 0.47159091 | U3: 93 | V3: 0.52840906 | W3: 9 | X3: 0.051136363 | Y3: 57 | Z3: 0.32386363 | AA3: 105 | AB3: 0.59659094 | AC3: 3 | AD3: 0.017045455 | AE3: 2 | AF3: 0.011363637 | AG3: 60 | AH3: 0.34090909 | AI3: 16 | AJ3: 0.090909094 | AK3: 149 | AL3: 0.84659094 | AM3: 0.88851261
A4: 01M015 | B4: P.S. 015 Roberto Clemente | C4: 2016-17 | D4: 178 | E4: 17 | F4: 28 | G4: 33 | H4: 27 | I4: 31 | J4: 24 | K4: 18 | L4: 0 | M4: 0 | N4: 0 | O4: 0 | P4: 0 | Q4: 0 | R4: 0 | S4: 83 | T4: 0.46629214 | U4: 95 | V4: 0.53370786 | W4: 14 | X4: 0.078651689 | Y4: 51 | Z4: 0.28651685 | AA4: 105 | AB4: 0.58988762 | AC4: 4 | AD4: 0.02247191 | AE4: 4 | AF4: 0.02247191 | AG4: 51 | AH4: 0.28651685 | AI4: 12 | AJ4: 0.067415729 | AK4: 152 | AL4: 0.85393256 | AM4: 0.88235396
A5: 01M015 | B5: P.S. 015 Roberto Clemente | C5: 2017-18 | D5: 190 | E5: 17 | F5: 28 | G5: 32 | H5: 33 | I5: 23 | J5: 31 | K5: 26 | L5: 0 | M5: 0 | N5: 0 | O5: 0 | P5: 0 | Q5: 0 | R5: 0 | S5: 99 | T5: 0.52105266 | U5: 91 | V5: 0.47894737 | W5: 20 | X5: 0.10526316 | Y5: 52 | Z5: 0.2736842 | AA5: 110 | AB5: 0.57894737 | AC5: 2 | AD5: 0.010526316 | AE5: 6 | AF5: 0.031578947 | AG5: 49 | AH5: 0.25789472 | AI5: 8 | AJ5: 0.042105265 | AK5: 161 | AL5: 0.84736842 | AM5: 0.88960528
A6: 01M015 | B6: P.S. 015 Roberto Clemente | C6: 2018-19 | D6: 174 | E6: 13 | F6: 20 | G6: 33 | H6: 30 | I6: 30 | J6: 20 | K6: 28 | L6: 0 | M6: 0 | N6: 0 | O6: 0 | P6: 0 | Q6: 0 | R6: 0 | S6: 85 | T6: 0.48850575 | U6: 89 | V6: 0.51149428 | W6: 24 | X6: 0.13793103 | Y6: 48 | Z6: 0.27586207 | AA6: 95 | AB6: 0.545977 | AC6: 1 | AD6: 0.0057471264 | AE6: 6 | AF6: 0.034482758 | AG6: 38 | AH6: 0.21839081 | AI6: 8 | AJ6: 0.045977011 | AK6: 145 | AL6: 0.83333331 | AM6: 0.87978739
A7: 01M019 | B7: P.S. 019 Asher Levy | C7: 2014-15 | D7: 270 | E7: 30 | F7: 44 | G7: 40 | H7: 39 | I7: 35 | J7: 40 | K7: 42 | L7: 0 | M7: 0 | N7: 0 | O7: 0 | P7: 0 | Q7: 0 | R7: 0 | S7: 132 | T7: 0.48888889 | U7: 138 | V7: 0.51111114 | W7: 30 | X7: 0.11111111 | Y7: 47 | Z7: 0.17407407 | AA7: 158 | AB7: 0.58518517 | AC7: 8 | AD7: 0.029629629 | AE7: 27 | AF7: 0.1 | AG7: 82 | AH7: 0.3037037 | AI7: 18 | AJ7: 0.06666667 | AK7: 200 | AL7: 0.74074072 | AM7: 0.60517448
A8: 01M019 | B8: P.S. 019 Asher Levy | C8: 2015-16 | D8: 270 | E8: 21 | F8: 47 | G8: 43 | H8: 41 | I8: 43 | J8: 35 | K8: 40 | L8: 0 | M8: 0 | N8: 0 | O8: 0 | P8: 0 | Q8: 0 | R8: 0 | S8: 125 | T8: 0.46296296 | U8: 145 | V8: 0.53703701 | W8: 27 | X8: 0.1 | Y8: 55 | Z8: 0.2037037 | AA8: 169 | AB8: 0.6259259 | AC8: 3 | AD8: 0.011111111 | AE8: 16 | AF8: 0.059259258 | AG8: 82 | AH8: 0.3037037 | AI8: 13 | AJ8: 0.048148148 | AK8: 217 | AL8: 0.80370373 | AM8: 0.62495583
A9: 01M019 | B9: P.S. 019 Asher Levy | C9: 2016-17 | D9: 271 | E9: 24 | F9: 37 | G9: 46 | H9: 47 | I9: 40 | J9: 43 | K9: 34 | L9: 0 | M9: 0 | N9: 0 | O9: 0 | P9: 0 | Q9: 0 | R9: 0 | S9: 127 | T9: 0.46863469 | U9: 144 | V9: 0.53136533 | W9: 24 | X9: 0.088560887 | Y9: 51 | Z9: 0.18819188 | AA9: 180 | AB9: 0.66420662 | AC9: 1 | AD9: 0.0036900369 | AE9: 15 | AF9: 0.055350553 | AG9: 88 | AH9: 0.32472324 | AI9: 9 | AJ9: 0.033210333 | AK9: 207 | AL9: 0.76383764 | AM9: 0.57811809
A10: 01M019 | B10: P.S. 019 Asher Levy | C10: 2017-18 | D10: 257 | E10: 13 | F10: 34 | G10: 38 | H10: 42 | I10: 46 | J10: 42 | K10: 42 | L10: 0 | M10: 0 | N10: 0 | O10: 0 | P10: 0 | Q10: 0 | R10: 0 | S10: 114 | T10: 0.44357976 | U10: 143 | V10: 0.55642021 | W10: 23 | X10: 0.089494161 | Y10: 49 | Z10: 0.19066148 | AA10: 166 | AB10: 0.64591438 | AC10: 3 | AD10: 0.011673152 | AE10: 16 | AF10: 0.062256809 | AG10: 90 | AH10: 0.35019454 | AI10: 8 | AJ10: 0.031128405 | AK10: 198 | AL10: 0.770428 | AM10: 0.67860699
A11: 01M019 | B11: P.S. 019 Asher Levy | C11: 2018-19 | D11: 249 | E11: 10 | F11: 30 | G11: 39 | H11: 43 | I11: 41 | J11: 44 | K11: 42 | L11: 0 | M11: 0 | N11: 0 | O11: 0 | P11: 0 | Q11: 0 | R11: 0 | S11: 114 | T11: 0.45783132 | U11: 135 | V11: 0.54216868 | W11: 14 | X11: 0.056224901 | Y11: 52 | Z11: 0.20883535 | AA11: 156 | AB11: 0.62650603 | AC11: 9 | AD11: 0.036144577 | AE11: 18 | AF11: 0.072289154 | AG11: 92 | AH11: 0.3694779 | AI11: 8 | AJ11: 0.032128513 | AK11: 180 | AL11: 0.72289157 | AM11: 0.66802025
A12: 01M020 | B12: P.S. 020 Anna Silver | C12: 2014-15 | D12: 633 | E12: 51 | F12: 102 | G12: 108 | H12: 100 | I12: 98 | J12: 104 | K12: 70 | L12: 0 | M12: 0 | N12: 0 | O12: 0 | P12: 0 | Q12: 0 | R12: 0 | S12: 301 | T12: 0.47551343 | U12: 332 | V12: 0.5244866 | W12: 231 | X12: 0.3649289 | Y12: 53 | Z12: 0.083728276 | AA12: 309 | AB12: 0.48815167 | AC12: 15 | AD12: 0.023696683 | AE12: 25 | AF12: 0.03949447 | AG12: 144 | AH12: 0.22748815 | AI12: 120 | AJ12: 0.18957347 | AK12: 411 | AL12: 0.64928907 | AM12: 0.71813703
A13: 01M020 | B13: P.S. 020 Anna Silver | C13: 2015-16 | D13: 581 | E13: 46 | F13: 82 | G13: 90 | H13: 98 | I13: 92 | J13: 81 | K13: 92 | L13: 0 | M13: 0 | N13: 0 | O13: 0 | P13: 0 | Q13: 0 | R13: 0 | S13: 277 | T13: 0.4767642 | U13: 304 | V13: 0.5232358 | W13: 204 | X13: 0.35111877 | Y13: 46 | Z13: 0.079173841 | AA13: 286 | AB13: 0.49225473 | AC13: 21 | AD13: 0.036144577 | AE13: 24 | AF13: 0.04130809 | AG13: 123 | AH13: 0.21170396 | AI13: 88 | AJ13: 0.151463 | AK13: 353 | AL13: 0.60757315 | AM13: 0.67413688
... A7817: 75X811 | B7817: P.S. X811 | C7817: 2018-19 | D7817: 634 | E7817: 0 | F7817: 0 | G7817: 0 | H7817: 0 | I7817: 0 | J7817: 0 | K7817: 0 | L7817: 0 | M7817: 1 | N7817: 1 | O7817: 78 | P7817: 114 | Q7817: 86 | R7817: 354 | S7817: 192 | T7817: 0.30283913 | U7817: 442 | V7817: 0.6971609 | W7817: 20 | X7817: 0.03154574 | Y7817: 218 | Z7817: 0.34384859 | AA7817: 366 | AB7817: 0.57728708 | AC7817: 7 | AD7817: 0.01104101 | AE7817: 23 | AF7817: 0.036277603 | AG7817: 632 | AH7817: 0.99684542 | AI7817: 241 | AJ7817: 0.38012618 | AK7817: 589 | AL7817: 0.92902207 | AM7817: 0.95561832
